<mujoco>
  <worldbody>
    <light diffuse="1 1 1" pos="0 0 3" dir="0 0 -1"/>
    <body name="link1" pos="1 0 1" euler="0 0 0">
      <geom type="capsule" fromto="0 0 0  0 0 -0.5" size="0.05" rgba="0.8 0.2 0.2 1"/>
      <body name="link2" pos="0 0 -0.5">
        <joint name="joint1" type="hinge" axis="0 1 0" damping="0.1"/>
        <geom type="capsule" fromto="0 0 0  0 0 -0.5" size="0.05" rgba="0.2 0.8 0.2 1"/>
      </body>
    </body>
  </worldbody>

  <actuator>
    <position name="servo_joint1" joint="joint1" kp="50"/>
  </actuator>
</mujoco>
